Workbook

Sheet SCH DATA NH
A3: SL | B3: ROUTE | C3: FIX BM | D3: VEHICLE | E3: SWAP | F3: BM NO | G3: REG NO | H3: OUT TIME | I3: IN TIME
A4: 1 | B4: 600F/91 | C4: BM248 | D4: =_xlfn.XLOOKUP($C4,VEH.NO!$B$2:$B$123,VEH.NO!$C$2:$C$123,"",0,1) -> KA51AH4797 | F4: BM248 | G4: =IFERROR(VLOOKUP(F4,'[1]VH NO WISE'!$B$2:$C$123,2,0),"") -> KA51AH4797 | H4: 0.52083333 | I4: 0.44444444
A5: =A4+1 -> 2 | B5: 600F/92 | C5: BM278 | D5: =_xlfn.XLOOKUP($C5,VEH.NO!$B$2:$B$123,VEH.NO!$C$2:$C$123,"",0,1) -> KA51AH6246 | F5: BM283 | G5: =IFERROR(VLOOKUP(F5,'[1]VH NO WISE'!$B$2:$C$123,2,0),"") -> KA51AH6249 | H5: 0.52777778 | I5: 0.45486111
A6: =A5+1 -> 3 | B6: 600F/93 | C6: BM200 | D6: =_xlfn.XLOOKUP($C6,VEH.NO!$B$2:$B$123,VEH.NO!$C$2:$C$123,"",0,1) -> KA51AH7659 | F6: BM200 | G6: =IFERROR(VLOOKUP(F6,'[1]VH NO WISE'!$B$2:$C$123,2,0),"") -> KA51AH7659 | H6: 0.53472222 | I6: 0.46180556
A7: =A6+1 -> 4 | B7: 600F/94 | C7: BM201 | D7: =_xlfn.XLOOKUP($C7,VEH.NO!$B$2:$B$123,VEH.NO!$C$2:$C$123,"",0,1) -> KA51AH7656 | F7: BM215 | G7: =IFERROR(VLOOKUP(F7,'[1]VH NO WISE'!$B$2:$C$123,2,0),"") -> KA51AH8346 | H7: 0.54166667 | I7: 0.46875
A8: =A7+1 -> 5 | B8: 328H/2 | C8: BM294 | D8: =_xlfn.XLOOKUP($C8,VEH.NO!$B$2:$B$123,VEH.NO!$C$2:$C$123,"",0,1) -> KA51AH6777 | F8: BM294 | G8: =IFERROR(VLOOKUP(F8,'[1]VH NO WISE'!$B$2:$C$123,2,0),"") -> KA51AH6777 | H8: 0.54166667 | I8: 0.44791667
A9: =A8+1 -> 6 | B9: 361C/1 | C9: BM299 | D9: =_xlfn.XLOOKUP($C9,VEH.NO!$B$2:$B$123,VEH.NO!$C$2:$C$123,"",0,1) -> KA51AH7663 | F9: BM299 | G9: =IFERROR(VLOOKUP(F9,'[1]VH NO WISE'!$B$2:$C$123,2,0),"") -> KA51AH7663 | H9: 0.54861111 | I9: 0.48611111
A10: =A9+1 -> 7 | B10: 600F/95 | C10: BM223 | D10: =_xlfn.XLOOKUP($C10,VEH.NO!$B$2:$B$123,VEH.NO!$C$2:$C$123,"",0,1) -> KA51AH8283 | F10: BM223 | G10: =IFERROR(VLOOKUP(F10,'[1]VH NO WISE'!$B$2:$C$123,2,0),"") -> KA51AH8283 | H10: 0.54861111 | I10: 0.47569444
A11: =A10+1 -> 8 | B11: 328H/1 | C11: BM153 | D11: =_xlfn.XLOOKUP($C11,VEH.NO!$B$2:$B$123,VEH.NO!$C$2:$C$123,"",0,1) -> KA51AH4643 | F11: BM024 | G11: =IFERROR(VLOOKUP(F11,'[1]VH NO WISE'!$B$2:$C$123,2,0),"") -> KA51AH2619 | H11: 0.54861111 | I11: 0.4375
A12: =A11+1 -> 9 | B12: 600F/52 | C12: BM281 | D12: =_xlfn.XLOOKUP($C12,VEH.NO!$B$2:$B$123,VEH.NO!$C$2:$C$123,"",0,1) -> KA51AH6251 | F12: BM281 | G12: =IFERROR(VLOOKUP(F12,'[1]VH NO WISE'!$B$2:$C$123,2,0),"") -> KA51AH6251 | H12: 0.55208333 | I12: 0.48958333
A13: =A12+1 -> 10 | B13: 399C/3 | C13: BM216 | D13: =_xlfn.XLOOKUP($C13,VEH.NO!$B$2:$B$123,VEH.NO!$C$2:$C$123,"",0,1) -> KA51AH8281 | F13: BM088 | G13: =IFERROR(VLOOKUP(F13,'[1]VH NO WISE'!$B$2:$C$123,2,0),"") -> KA51AH3127 | H13: 0.55208333 | I13: 0.46527778
A14: =A13+1 -> 11 | B14: 328H/3 | C14: BM183 | D14: =_xlfn.XLOOKUP($C14,VEH.NO!$B$2:$B$123,VEH.NO!$C$2:$C$123,"",0,1) -> KA51AH5825 | F14: BM068 | G14: =IFERROR(VLOOKUP(F14,'[1]VH NO WISE'!$B$2:$C$123,2,0),"") -> KA51AH3266 | H14: 0.55555556 | I14: 0.44444444
A15: =A14+1 -> 12 | B15: 328H/6 | C15: BM068 | D15: =_xlfn.XLOOKUP($C15,VEH.NO!$B$2:$B$123,VEH.NO!$C$2:$C$123,"",0,1) -> KA51AH3266 | F15: BM057 | G15: =IFERROR(VLOOKUP(F15,'[1]VH NO WISE'!$B$2:$C$123,2,0),"") -> KA51AH2956 | H15: 0.55555556 | I15: 0.47569444
A16: =A15+1 -> 13 | B16: 600F/57 | C16: BM215 | D16: =_xlfn.XLOOKUP($C16,VEH.NO!$B$2:$B$123,VEH.NO!$C$2:$C$123,"",0,1) -> KA51AH8346 | G16: =IFERROR(VLOOKUP(F16,'[1]VH NO WISE'!$B$2:$C$123,2,0),"") | H16: 0.55902778 | I16: 0.49652778
A17: =A16+1 -> 14 | B17: 361C/2 | C17: BM054 | D17: =_xlfn.XLOOKUP($C17,VEH.NO!$B$2:$B$123,VEH.NO!$C$2:$C$123,"",0,1) -> KA51AH2951 | F17: BM054 | G17: =IFERROR(VLOOKUP(F17,'[1]VH NO WISE'!$B$2:$C$123,2,0),"") -> KA51AH2951 | H17: 0.5625 | I17: 0.5
A18: =A17+1 -> 15 | B18: 328H/9 | C18: BM207 | D18: =_xlfn.XLOOKUP($C18,VEH.NO!$B$2:$B$123,VEH.NO!$C$2:$C$123,"",0,1) -> KA51AH7671 | F18: BM207 | G18: =IFERROR(VLOOKUP(F18,'[1]VH NO WISE'!$B$2:$C$123,2,0),"") -> KA51AH7671 | H18: 0.5625 | I18: 0.45138889
A19: =A18+1 -> 16 | B19: 600F/49 | C19: BM255 | D19: =_xlfn.XLOOKUP($C19,VEH.NO!$B$2:$B$123,VEH.NO!$C$2:$C$123,"",0,1) -> KA51AH5640 | F19: BM255 | G19: =IFERROR(VLOOKUP(F19,'[1]VH NO WISE'!$B$2:$C$123,2,0),"") -> KA51AH5640 | H19: 0.56597222 | I19: 0.50347222
A20: =A19+1 -> 17 | B20: KBS3A/2 | C20: BM086 | D20: =_xlfn.XLOOKUP($C20,VEH.NO!$B$2:$B$123,VEH.NO!$C$2:$C$123,"",0,1) -> KA51AH3125 | F20: BM081 | G20: =IFERROR(VLOOKUP(F20,'[1]VH NO WISE'!$B$2:$C$123,2,0),"") -> KA51AH3129 | H20: 0.56597222 | I20: 0.44097222
A21: =A20+1 -> 18 | B21: 600F/51 | C21: BM273 | D21: =_xlfn.XLOOKUP($C21,VEH.NO!$B$2:$B$123,VEH.NO!$C$2:$C$123,"",0,1) -> KA51AH6098 | F21: BM273 | G21: =IFERROR(VLOOKUP(F21,'[1]VH NO WISE'!$B$2:$C$123,2,0),"") -> KA51AH6098 | H21: 0.57291667 | I21: 0.51041667
A22: =A21+1 -> 19 | B22: KBS3A/20 | C22: BM268 | D22: =_xlfn.XLOOKUP($C22,VEH.NO!$B$2:$B$123,VEH.NO!$C$2:$C$123,"",0,1) -> KA51AH6035 | F22: BM268 | G22: =IFERROR(VLOOKUP(F22,'[1]VH NO WISE'!$B$2:$C$123,2,0),"") -> KA51AH6035 | H22: 0.57291667 | I22: 0.44791667
A23: =A22+1 -> 20 | B23: 328H/10 | C23: BM285 | D23: =_xlfn.XLOOKUP($C23,VEH.NO!$B$2:$B$123,VEH.NO!$C$2:$C$123,"",0,1) -> KA51AH6252 | F23: BM285 | G23: =IFERROR(VLOOKUP(F23,'[1]VH NO WISE'!$B$2:$C$123,2,0),"") -> KA51AH6252 | H23: 0.57291667 | I23: 0.48958333
A24: =A23+1 -> 21 | B24: KBS3F/16 | C24: BM082 | D24: =_xlfn.XLOOKUP($C24,VEH.NO!$B$2:$B$123,VEH.NO!$C$2:$C$123,"",0,1) -> KA51AH3131 | F24: BM082 | G24: =IFERROR(VLOOKUP(F24,'[1]VH NO WISE'!$B$2:$C$123,2,0),"") -> KA51AH3131 | H24: 0.57638889 | I24: 0.48611111
A25: =A24+1 -> 22 | B25: 328H/12 | C25: BM224 | D25: =_xlfn.XLOOKUP($C25,VEH.NO!$B$2:$B$123,VEH.NO!$C$2:$C$123,"",0,1) -> KA51AH8185 | F25: BM224 | G25: =IFERROR(VLOOKUP(F25,'[1]VH NO WISE'!$B$2:$C$123,2,0),"") -> KA51AH8185 | H25: 0.57638889 | I25: 0.46527778
A26: =A25+1 -> 23 | B26: 361C/3 | C26: BM289 | D26: =_xlfn.XLOOKUP($C26,VEH.NO!$B$2:$B$123,VEH.NO!$C$2:$C$123,"",0,1) -> KA51AH6471 | F26: BM289 | G26: =IFERROR(VLOOKUP(F26,'[1]VH NO WISE'!$B$2:$C$123,2,0),"") -> KA51AH6471 | H26: 0.57638889 | I26: 0.51388889
A27: =A26+1 -> 24 | B27: 600F/5 | C27: BM274 | D27: =_xlfn.XLOOKUP($C27,VEH.NO!$B$2:$B$123,VEH.NO!$C$2:$C$123,"",0,1) -> KA51AH6099 | F27: BM274 | G27: =IFERROR(VLOOKUP(F27,'[1]VH NO WISE'!$B$2:$C$123,2,0),"") -> KA51AH6099 | H27: 0.57986111 | I27: 0.51736111
A28: =A27+1 -> 25 | B28: KBS3A/23 | C28: BM259 | D28: =_xlfn.XLOOKUP($C28,VEH.NO!$B$2:$B$123,VEH.NO!$C$2:$C$123,"",0,1) -> KA51AH5642 | F28: BM259 | G28: =IFERROR(VLOOKUP(F28,'[1]VH NO WISE'!$B$2:$C$123,2,0),"") -> KA51AH5642 | H28: 0.57986111 | I28: 0.45486111
... A43: =A42+1 -> 40 | B43: 361C/11 | C43: BM304 | D43: =_xlfn.XLOOKUP($C43,VEH.NO!$B$2:$B$123,VEH.NO!$C$2:$C$123,"",0,1) -> KA51AJ0137 | F43: BM304 | G43: =IFERROR(VLOOKUP(F43,'[1]VH NO WISE'!$B$2:$C$123,2,0),"") -> KA51AJ0137 | H43: 0.60416667 | I43: 0.54166667
A44: =A43+1 -> 41 | B44: 328H/20 | C44: BM204 | D44: =_xlfn.XLOOKUP($C44,VEH.NO!$B$2:$B$123,VEH.NO!$C$2:$C$123,"",0,1) -> KA51AH7666 | G44: =IFERROR(VLOOKUP(F44,'[1]VH NO WISE'!$B$2:$C$123,2,0),"") | H44: 0.60416667 | I44: 0.52083333
A45: =A44+1 -> 42 | B45: 356Z/8 | C45: BM218 | D45: =_xlfn.XLOOKUP($C45,VEH.NO!$B$2:$B$123,VEH.NO!$C$2:$C$123,"",0,1) -> KA51AH8182 | F45: BM303 | G45: =IFERROR(VLOOKUP(F45,'[1]VH NO WISE'!$B$2:$C$123,2,0),"") -> KA51AJ0138 | H45: 0.60763889 | I45: 0.51388889
A46: =A45+1 -> 43 | B46: 600F/74 | C46: BM271 | D46: =_xlfn.XLOOKUP($C46,VEH.NO!$B$2:$B$123,VEH.NO!$C$2:$C$123,"",0,1) -> KA51AH6095 | F46: BM271 | G46: =IFERROR(VLOOKUP(F46,'[1]VH NO WISE'!$B$2:$C$123,2,0),"") -> KA51AH6095 | H46: 0.60763889 | I46: 0.54513889
A47: =A46+1 -> 44 | B47: KBS3A/77 | C47: BM062 | D47: =_xlfn.XLOOKUP($C47,VEH.NO!$B$2:$B$123,VEH.NO!$C$2:$C$123,"",0,1) -> KA51AH3269 | F47: BM062 | G47: =IFERROR(VLOOKUP(F47,'[1]VH NO WISE'!$B$2:$C$123,2,0),"") -> KA51AH3269 | H47: 0.60763889 | I47: 0.48263889
A48: =A47+1 -> 45 | B48: 399C/5 | C48: BM272 | D48: =_xlfn.XLOOKUP($C48,VEH.NO!$B$2:$B$123,VEH.NO!$C$2:$C$123,"",0,1) -> KA51AH6097 | F48: BM272 | G48: =IFERROR(VLOOKUP(F48,'[1]VH NO WISE'!$B$2:$C$123,2,0),"") -> KA51AH6097 | H48: 0.61111111 | I48: 0.57638889
A49: =A48+1 -> 46 | B49: 600F/75 | C49: BM058 | D49: =_xlfn.XLOOKUP($C49,VEH.NO!$B$2:$B$123,VEH.NO!$C$2:$C$123,"",0,1) -> KA51AH3603 | F49: BM214 | G49: =IFERROR(VLOOKUP(F49,'[1]VH NO WISE'!$B$2:$C$123,2,0),"") -> KA51AH8348 | H49: 0.61458333 | I49: 0.55208333
A50: =A49+1 -> 47 | B50: KBS3A/78 | C50: BM245 | D50: =_xlfn.XLOOKUP($C50,VEH.NO!$B$2:$B$123,VEH.NO!$C$2:$C$123,"",0,1) -> KA51AH4799 | F50: BM005 | G50: =IFERROR(VLOOKUP(F50,'[1]VH NO WISE'!$B$2:$C$123,2,0),"") -> KA51AH2421 | H50: 0.61458333 | I50: 0.48958333
A51: =A50+1 -> 48 | B51: 328H/23 | C51: BM212 | D51: =_xlfn.XLOOKUP($C51,VEH.NO!$B$2:$B$123,VEH.NO!$C$2:$C$123,"",0,1) -> KA51AH7779 | F51: BM212 | G51: =IFERROR(VLOOKUP(F51,'[1]VH NO WISE'!$B$2:$C$123,2,0),"") -> KA51AH7779 | H51: 0.61458333 | I51: 0.53125
A52: =A51+1 -> 49 | B52: 361C/6 | C52: BM225 | D52: =_xlfn.XLOOKUP($C52,VEH.NO!$B$2:$B$123,VEH.NO!$C$2:$C$123,"",0,1) -> KA51AH8349 | F52: BM225 | G52: =IFERROR(VLOOKUP(F52,'[1]VH NO WISE'!$B$2:$C$123,2,0),"") -> KA51AH8349 | H52: 0.61805556 | I52: 0.55555556
A53: =A52+1 -> 50 | B53: 600F/79 | C53: BM295 | D53: =_xlfn.XLOOKUP($C53,VEH.NO!$B$2:$B$123,VEH.NO!$C$2:$C$123,"",0,1) -> KA51AH6780 | F53: BM245 | G53: =IFERROR(VLOOKUP(F53,'[1]VH NO WISE'!$B$2:$C$123,2,0),"") -> KA51AH4799 | H53: 0.62152778 | I53: 0.55902778
A54: =A53+1 -> 51 | B54: KBS3A/79 | C54: BM297 | D54: =_xlfn.XLOOKUP($C54,VEH.NO!$B$2:$B$123,VEH.NO!$C$2:$C$123,"",0,1) -> KA51AH6472 | F54: BM209 | G54: =IFERROR(VLOOKUP(F54,'[1]VH NO WISE'!$B$2:$C$123,2,0),"") -> KA51AH7668 | H54: 0.62152778 | I54: 0.49652778
A55: =A54+1 -> 52 | B55: 328H/22 | C55: BM157 | D55: =_xlfn.XLOOKUP($C55,VEH.NO!$B$2:$B$123,VEH.NO!$C$2:$C$123,"",0,1) -> KA51AH4800 | F55: BM058 | G55: =IFERROR(VLOOKUP(F55,'[1]VH NO WISE'!$B$2:$C$123,2,0),"") -> KA51AH3603 | H55: 0.625 | I55: 0.54166667
A56: =A55+1 -> 53 | B56: KBS3A/80 | C56: BM010 | D56: =_xlfn.XLOOKUP($C56,VEH.NO!$B$2:$B$123,VEH.NO!$C$2:$C$123,"",0,1) -> KA51AH2424 | F56: BM020 | G56: =IFERROR(VLOOKUP(F56,'[1]VH NO WISE'!$B$2:$C$123,2,0),"") -> KA51AH2556 | H56: 0.62847222 | I56: 0.50347222
...

Sheet VEH.NO
A1: SL NO | B1: BM NO | C1: REG NO
A2: 1 | B2: BM001 | C2: KA51AH4144
A3: 2 | B3: BM002 | C3: KA51AH2434
A4: 3 | B4: BM003 | C4: KA51AH2423
A5: 4 | B5: BM004 | C5: KA51AH2429
A6: 5 | B6: BM005 | C6: KA51AH2421
A7: 6 | B7: BM010 | C7: KA51AH2424
A8: 7 | B8: BM012 | C8: KA51AH2551
A9: 8 | B9: BM019 | C9: KA51AH2552
A10: 9 | B10: BM020 | C10: KA51AH2556
A11: 10 | B11: BM024 | C11: KA51AH2619
A12: 11 | B12: BM032 | C12: KA51AH2739
A13: 12 | B13: BM033 | C13: KA51AH2740
... A123: 122 | B123: BM304 | C123: KA51AJ0137

Sheet Sheet1

Sheet Sheet2
A2: SHIFT A VEHICLES
A3: SL NO. | B3: ROUTE | C3: FIX BM | D3: VEHICLE | E3: OUT TIME | F3: IN TIME
A4: 1 | B4: 356Z/7 | C4: BM256 | D4: =_xlfn.XLOOKUP($C4,VEH.NO!$B$2:$B$123,VEH.NO!$C$2:$C$123,"",0,1) -> KA51AH5641 | E4: 0.57291667 | F4: 0.54166667
A5: 2 | B5: 356Z/6 | C5: BM217 | D5: =_xlfn.XLOOKUP($C5,VEH.NO!$B$2:$B$123,VEH.NO!$C$2:$C$123,"",0,1) -> KA51AH8284 | E5: 0.58333333 | F5: 0.55208333
A6: 3 | B6: 360K/3 | C6: BM205 | D6: =_xlfn.XLOOKUP($C6,VEH.NO!$B$2:$B$123,VEH.NO!$C$2:$C$123,"",0,1) -> KA51AH7673 | E6: 0.58680556 | F6: 0.55555556
A7: 4 | B7: 360K/4 | C7: BM214 | D7: =_xlfn.XLOOKUP($C7,VEH.NO!$B$2:$B$123,VEH.NO!$C$2:$C$123,"",0,1) -> KA51AH8348 | E7: 0.59375 | F7: 0.5625
A8: 5 | B8: 600F/80 | C8: BM056 | D8: =_xlfn.XLOOKUP($C8,VEH.NO!$B$2:$B$123,VEH.NO!$C$2:$C$123,"",0,1) -> KA51AH2953 | E8: 0.59375 | F8: 0.5625
A9: 6 | B9: 360K/15 | C9: BM291 | D9: =_xlfn.XLOOKUP($C9,VEH.NO!$B$2:$B$123,VEH.NO!$C$2:$C$123,"",0,1) -> KA51AH6466 | E9: 0.60069444 | F9: 0.56944444
A10: 7 | B10: 600F/53 | C10: BM264 | D10: =_xlfn.XLOOKUP($C10,VEH.NO!$B$2:$B$123,VEH.NO!$C$2:$C$123,"",0,1) -> KA51AH6037 | E10: 0.60416667 | F10: 0.57291667
A11: 8 | B11: 360K/30 | C11: BM292 | D11: =_xlfn.XLOOKUP($C11,VEH.NO!$B$2:$B$123,VEH.NO!$C$2:$C$123,"",0,1) -> KA51AH6468 | E11: 0.60763889 | F11: 0.57638889
A12: 9 | B12: 600F/66 | C12: BM198 | D12: =_xlfn.XLOOKUP($C12,VEH.NO!$B$2:$B$123,VEH.NO!$C$2:$C$123,"",0,1) -> KA51AH7664 | E12: 0.61111111 | F12: 0.57986111
A13: 10 | B13: 360K/38 | C13: BM199 | D13: =_xlfn.XLOOKUP($C13,VEH.NO!$B$2:$B$123,VEH.NO!$C$2:$C$123,"",0,1) -> KA51AH7662 | E13: 0.61458333 | F13: 0.58333333
A14: GENARAL SHIFT VEHICLES
A15: SL NO. | B15: ROUTE | C15: FIX BM | D15: VEHICLE | E15: OUT TIME | F15: IN TIME
A16: 1 | B16: 600F/21 | C16: BM298 | D16: KA51AH6778
A17: 2 | B17: 600F/16 | C17: BM003 | D17: KA51AH2423
A18: 3 | B18: 600F/17 | C18: BM277 | D18: KA51AH6245
A19: 4 | B19: 600F/26 | C19: BM258 | D19: KA51AH5643
A20: 5 | B20: 600F/27 | C20: BM208 | D20: KA51AH7775
A21: 6 | B21: 600F/3 | C21: BM249 | D21: KA51AH6029
A22: 7 | B22: 600F/31 | C22: BM265 | D22: KA51AH5723
A23: 8 | B23: 600F/42 | C23: BM261 | D23: KA51AH5717
A24: 9 | B24: 600F/43 | C24: BM203 | D24: KA51AH7670
A25: 10 | B25: 600F/45 | C25: BM010 | D25: KA51AH2424
